[2023-10-07 08:10:43,521] {taskinstance.py:1159} INFO - Dependencies all met for <TaskInstance: sales_mart.check_incr scheduled__2023-10-06T08:05:25.664213+00:00 [queued]>
[2023-10-07 08:10:43,527] {taskinstance.py:1159} INFO - Dependencies all met for <TaskInstance: sales_mart.check_incr scheduled__2023-10-06T08:05:25.664213+00:00 [queued]>
[2023-10-07 08:10:43,528] {taskinstance.py:1356} INFO - 
--------------------------------------------------------------------------------
[2023-10-07 08:10:43,528] {taskinstance.py:1357} INFO - Starting attempt 1 of 1
[2023-10-07 08:10:43,529] {taskinstance.py:1358} INFO - 
--------------------------------------------------------------------------------
[2023-10-07 08:10:43,538] {taskinstance.py:1377} INFO - Executing <Task(BranchPythonOperator): check_incr> on 2023-10-06 08:05:25.664213+00:00
[2023-10-07 08:10:43,541] {standard_task_runner.py:52} INFO - Started process 1630 to run task
[2023-10-07 08:10:43,543] {standard_task_runner.py:79} INFO - Running: ['airflow', 'tasks', 'run', 'sales_mart', 'check_incr', 'scheduled__2023-10-06T08:05:25.664213+00:00', '--job-id', '33', '--raw', '--subdir', 'DAGS_FOLDER/sprint3.py', '--cfg-path', '/tmp/tmpgrxx9ryl', '--error-file', '/tmp/tmpy_551dr3']
[2023-10-07 08:10:43,544] {standard_task_runner.py:80} INFO - Job 33: Subtask check_incr
[2023-10-07 08:10:43,584] {task_command.py:369} INFO - Running <TaskInstance: sales_mart.check_incr scheduled__2023-10-06T08:05:25.664213+00:00 [running]> on host 219fbcc16ca0
[2023-10-07 08:10:43,629] {taskinstance.py:1569} INFO - Exporting the following env vars:
AIRFLOW_CTX_DAG_EMAIL=student@example.com
AIRFLOW_CTX_DAG_OWNER=student
AIRFLOW_CTX_DAG_ID=sales_mart
AIRFLOW_CTX_TASK_ID=check_incr
AIRFLOW_CTX_EXECUTION_DATE=2023-10-06T08:05:25.664213+00:00
AIRFLOW_CTX_TRY_NUMBER=1
AIRFLOW_CTX_DAG_RUN_ID=scheduled__2023-10-06T08:05:25.664213+00:00
[2023-10-07 08:10:43,630] {taskinstance.py:1889} ERROR - Task failed with exception
Traceback (most recent call last):
  File "/usr/local/lib/python3.8/dist-packages/airflow/operators/python.py", line 207, in execute
    branch = super().execute(context)
  File "/usr/local/lib/python3.8/dist-packages/airflow/operators/python.py", line 171, in execute
    return_value = self.execute_callable()
  File "/usr/local/lib/python3.8/dist-packages/airflow/operators/python.py", line 189, in execute_callable
    return self.python_callable(*self.op_args, **self.op_kwargs)
  File "/lessons/dags/sprint3.py", line 89, in if_increment
    if ti.xcom_pull(key='increment_id',task_id='get_increments')['status'] == 'SUCCESS':
  File "/usr/local/lib/python3.8/dist-packages/airflow/utils/session.py", line 71, in wrapper
    return func(*args, session=session, **kwargs)
TypeError: xcom_pull() got an unexpected keyword argument 'task_id'
[2023-10-07 08:10:43,644] {taskinstance.py:1395} INFO - Marking task as FAILED. dag_id=sales_mart, task_id=check_incr, execution_date=20231006T080525, start_date=20231007T081043, end_date=20231007T081043
[2023-10-07 08:10:43,650] {standard_task_runner.py:92} ERROR - Failed to execute job 33 for task check_incr (xcom_pull() got an unexpected keyword argument 'task_id'; 1630)
[2023-10-07 08:10:43,676] {local_task_job.py:156} INFO - Task exited with return code 1
[2023-10-07 08:10:43,706] {local_task_job.py:273} INFO - 0 downstream tasks scheduled from follow-on schedule check
